Traceback (most recent call last):
  File "C:\Users\edier\miniconda3\Lib\site-packages\jupyter_cache\executors\utils.py", line 58, in single_nb_execution
    executenb(
  File "C:\Users\edier\miniconda3\Lib\site-packages\nbclient\client.py", line 1305, in execute
    return NotebookClient(nb=nb, resources=resources, km=km, **kwargs).execute()
           ^^^^^^^^^^^^^^^^^^^^^^^^^^^^^^^^^^^^^^^^^^^^^^^^^^^^^^^^^^^^^^^^^^^^^
  File "C:\Users\edier\AppData\Roaming\Python\Python311\site-packages\jupyter_core\utils\__init__.py", line 166, in wrapped
    return loop.run_until_complete(inner)
           ^^^^^^^^^^^^^^^^^^^^^^^^^^^^^^
  File "C:\Users\edier\miniconda3\Lib\asyncio\base_events.py", line 653, in run_until_complete
    return future.result()
           ^^^^^^^^^^^^^^^
  File "C:\Users\edier\miniconda3\Lib\site-packages\nbclient\client.py", line 705, in async_execute
    await self.async_execute_cell(
  File "C:\Users\edier\miniconda3\Lib\site-packages\nbclient\client.py", line 1058, in async_execute_cell
    await self._check_raise_for_error(cell, cell_index, exec_reply)
  File "C:\Users\edier\miniconda3\Lib\site-packages\nbclient\client.py", line 914, in _check_raise_for_error
    raise CellExecutionError.from_cell_and_msg(cell, exec_reply_content)
nbclient.exceptions.CellExecutionError: An error occurred while executing the following cell:
------------------
w_a=(ap1/total1)/(ap/total)
w_b=(bp1/total1)/(bp/total)
w_c=(cp1/total1)/(cp/total)
w_d=(dp1/total1)/(dp/total)
w_e=(ep1/total1)/(ep/total)
print(w_a,w_b,w_c,w_d,w_e)
------------------


[1;31m---------------------------------------------------------------------------[0m
[1;31mNameError[0m                                 Traceback (most recent call last)
Cell [1;32mIn[7], line 1[0m
[1;32m----> 1[0m w_a[38;5;241m=[39m(ap1[38;5;241m/[39m[43mtotal1[49m)[38;5;241m/[39m(ap[38;5;241m/[39mtotal)
[0;32m      2[0m w_b[38;5;241m=[39m(bp1[38;5;241m/[39mtotal1)[38;5;241m/[39m(bp[38;5;241m/[39mtotal)
[0;32m      3[0m w_c[38;5;241m=[39m(cp1[38;5;241m/[39mtotal1)[38;5;241m/[39m(cp[38;5;241m/[39mtotal)

[1;31mNameError[0m: name 'total1' is not defined

